Workbook

Sheet Title
A1: MY LITTLE PIZZA FOOD TRUCK

Sheet Start-up-blank
A1: COMPANY LAUNCH ON DECEMBER 20th
B4: On December 20th, I invest my savings in a new business:
B5: Shareholder investment: | C5: 5000
B6: On December 22nd, I visit a supermarket to buy the ingredients I need:
B7: Food supply: | C7: 750
B8: I enjoy a nice Christmas break for now. I'm excited to begin operations on January 1st!
B11: CASH FLOW STATEMENT
B13: Cash beginning
B15: Cash in
B16: Share capital
B18: Cash out
B19: Food supply
B21: Cash end
B24: BALANCE SHEET END OF THE MONTH
B26: ASSETS | E26: LIABILITIES & EQUITY
B27: Inventory | E27: Share capital
B28: Cash
B29: Total assets | E29: Total liabilities & equity

Sheet Start-up
A1: COMPANY LAUNCH ON DECEMBER 20th
B4: On December 20th, I invest my savings in a new business:
B5: Shareholder investment: | C5: 5000
B6: On December 22nd, I visit a supermarket to buy the ingredients I need:
B7: Food supply: | C7: 750
B8: I enjoy a nice Christmas break for now. I'm excited to begin operations on January 1st!
B11: CASH FLOW STATEMENT
B13: Cash beginning | C13: 0
B15: Cash in
B16: Share capital | C16: =C5 -> 5000
B18: Cash out
B19: Food supply | C19: =-C7 -> -750
B21: Cash end | C21: =C13+C16+C19 -> 4250
B24: BALANCE SHEET END OF THE MONTH
B26: ASSETS | E26: LIABILITIES & EQUITY
B27: Inventory | C27: =C7 -> 750 | E27: Share capital | F27: =C5 -> 5000
B28: Cash | C28: =C21 -> 4250
B29: Total assets | C29: =SUM(C27:C28) -> 5000 | E29: Total liabilities & equity | F29: =F27 -> 5000

Sheet January-blank
A1: JANUARY
B4: I rent a truck: | C4: 2500
B5: I sell: | C5: 500
B6: The selling price is: | C6: 10 | D6: (all customers pay in cash)
B7: Besides the rental cost of the truck, I bear the following additional expenses:
B8: Material cost: | C8: 1.5 | D8: (food bought in December)
B9: Water & Electricity: | C9: 0.5
B12: PRODUCTION COST PER PIZZA
B14: Material cost
B15: Water & electricity
B16: Total
B20: INCOME STATEMENT | E20: CASH FLOW STATEMENT
B22: Sales revenue | E22: Cash beginning
B24: - Cost of pizzas sold | E24: Cash in
B25: - Truck rental cost | E25: Sales in cash
B27: Monthly profit | E27: Cash out
E28: Water & electricity
E29: Truck rental cost
E31: Cash end
B35: BALANCE SHEET END OF THE MONTH
B37: ASSETS | E37: LIABILITIES & EQUITY
B38: Inventory | E38: Share capital
B39: Cash | E39: Profit January
B40: Total assets | E40: Total liabilities & equity
B43: HOW MANY PIZZAS DO I NEED TO SELL TO COVER MY COSTS?
B45: At the break-even point, my sales revenue equals my total cost (cost of goods sold & truck rental cost), i.e. I make zero earnings.
B47: Break-even point:

Sheet January
A1: JANUARY
B4: I rent a truck: | C4: 2500
B5: I sell: | C5: 500
B6: The selling price is: | C6: 10 | D6: (all customers pay in cash)
B7: Besides the rental cost of the truck, I bear the following additional expenses:
B8: Material cost: | C8: 1.5 | D8: (food bought in December)
B9: Water & Electricity: | C9: 0.5
B12: PRODUCTION COST PER PIZZA
B14: Material cost | C14: =C8 -> 1.5
B15: Water & electricity | C15: =C9 -> 0.5
B16: Total | C16: =SUM(C14:C15) -> 2
B20: INCOME STATEMENT | E20: CASH FLOW STATEMENT
B22: Sales revenue | C22: =C5*C6 -> 5000 | E22: Cash beginning | F22: ='Start-up'!C28 -> 4250
B24: - Cost of pizzas sold | C24: =-C16*C5 -> -1000 | E24: Cash in
B25: - Truck rental cost | C25: =-C4 -> -2500 | E25: Sales in cash | F25: =C22 -> 5000
B27: Monthly profit | C27: =SUM(C22:C25) -> 1500 | E27: Cash out
E28: Water & electricity | F28: =-C9*C5 -> -250
E29: Truck rental cost | F29: =-C4 -> -2500
E31: Cash end | F31: =F22+SUM(F24:F25)+SUM(F27:F29) -> 6500
B35: BALANCE SHEET END OF THE MONTH
B37: ASSETS | E37: LIABILITIES & EQUITY
B38: Inventory | C38: ='Start-up'!C27-January!C14*January!C5 -> 0 | E38: Share capital | F38: ='Start-up'!F27 -> 5000
B39: Cash | C39: =F31 -> 6500 | E39: Profit January | F39: =C27 -> 1500
B40: Total assets | C40: =SUM(C38:C39) -> 6500 | E40: Total liabilities & equity | F40: =SUM(F38:F39) -> 6500
B43: HOW MANY PIZZAS DO I NEED TO SELL TO COVER MY COSTS?
B45: At the break-even point, my sales revenue equals my total cost (cost of goods sold & truck rental cost), i.e. I make zero earnings.
B47: Break-even point: | C47: =-C25/(C6-C16) -> 312.5

Sheet February-blank
A1: FEBRUARY
B4: I rent a truck: | C4: 2500
B5: I go back to the supermarket to purchase some more food:
B6: Food supply: | C6: 5000
B7: I sell: | C7: 1000 | D7: to individual customers who all pay in cash
B8: I closed a deal for: | C8: 2000 | D8: with a neighbouring company (payment terms: 30 days)
B9: The selling price is: | C9: 10 | D9: for all customers (individuals & the neighbouring company)
B10: Besides the rental cost of the truck, I bear the following additional expenses:
B11: Material cost: | C11: 1.5 | D11: (food bought at the supermarket earlier this month)
B12: Water & electricity: | C12: 0.5
B13: Part-time employee: | C13: 1000
B16: PRODUCTION COST PER PIZZA
B18: Material cost
B19: Water & electricity
B20: Total
B24: INCOME STATEMENT | E24: CASH FLOW STATEMENT
B26: Sales revenue | E26: Cash beginning
B28: - Cost of pizzas sold | E28: Cash in
B29: - Part-time employee | E29: Sales in cash
B31: - Truck rental cost | E31: Cash out
B32: Monthly profit | E32: Food supply
E33: Water & electricity
E34: Part-time employee
E35: Truck rental cost
E37: Cash end
B41: BALANCE SHEET END OF THE MONTH
B43: ASSETS | E43: LIABILITIES & EQUITY
B44: Inventory | E44: Share capital
B45: Accounts receivable | E45: Profit January
B46: Cash | E46: Profit February
B47: Total assets | E47: Total liabilities & equity

Sheet February
A1: FEBRUARY
B4: I rent a truck: | C4: 2500
B5: I go back to the supermarket to purchase some more food:
B6: Food supply: | C6: 5000
B7: I sell: | C7: 1000 | D7: to individual customers who all pay in cash
B8: I closed a deal for: | C8: 2000 | D8: with a neighbouring company (payment terms: 30 days)
B9: The selling price is: | C9: 10 | D9: for all customers (individuals & the neighbouring company)
B10: Besides the rental cost of the truck, I bear the following additional expenses:
B11: Material cost: | C11: 1.5 | D11: (food bought at the supermarket earlier this month)
B12: Water & electricity: | C12: 0.5
B13: Part-time employee: | C13: 1000
B16: PRODUCTION COST PER PIZZA
B18: Material cost | C18: =C11 -> 1.5
B19: Water & electricity | C19: =C12 -> 0.5
B20: Total | C20: =SUM(C18:C19) -> 2
B24: INCOME STATEMENT | E24: CASH FLOW STATEMENT
B26: Sales revenue | C26: =(C7+C8)*C9 -> 30000 | E26: Cash beginning | F26: =January!C39 -> 6500
B28: - Cost of pizzas sold | C28: =-C20*(C7+C8) -> -6000 | E28: Cash in
B29: - Part-time employee | C29: =-C13 -> -1000 | E29: Sales in cash | F29: =C7*C9 -> 10000
B31: - Truck rental cost | C31: =-C4 -> -2500 | E31: Cash out
B32: Monthly profit | C32: =SUM(C26:C31) -> 20500 | E32: Food supply | F32: =-C6 -> -5000
E33: Water & electricity | F33: =-C12*(C7+C8) -> -1500
E34: Part-time employee | F34: =-C13 -> -1000
E35: Truck rental cost | F35: =-C4 -> -2500
E37: Cash end | F37: =F26+SUM(F28:F29)+SUM(F31:F35) -> 6500
B41: BALANCE SHEET END OF THE MONTH
B43: ASSETS | E43: LIABILITIES & EQUITY
B44: Inventory | C44: =January!C38+February!C6-February!C18*(February!C7+February!C8) -> 500 | E44: Share capital | F44: ='Start-up'!F27 -> 5000
B45: Accounts receivable | C45: =C8*C9 -> 20000 | E45: Profit January | F45: =January!F39 -> 1500
B46: Cash | C46: =F37 -> 6500 | E46: Profit February | F46: =C32 -> 20500
B47: Total assets | C47: =SUM(C44:C46) -> 27000 | E47: Total liabilities & equity | F47: =SUM(F44:F46) -> 27000

Sheet March-blank
A1: MARCH
B4: I buy the truck for: | C4: 36000 | D4: (to be paid half in March and half in April)
B5: I will use the truck for: | C5: 3 | D5: in total
B6: I visit the supermarket once more to purchase food:
B7: Food supply: | C7: 5000
B8: I sell: | C8: 1000 | D8: to individual customers who all pay in cash
B9: Plus: | C9: 2000 | D9: to a neighbouring company (payment terms: 30 days)
B10: The selling price will be: | C10: 10 | D10: for all customers (individuals & the neighbouring company)
B11: I bear the following additional expenses:
B12: Material cost: | C12: 1.5 | D12: (past inventory & food just bought at the supermarket)
B13: Water & electricity: | C13: 0.5
B14: Part-time employee: | C14: 1000
B15: Truck insurance: | C15: 300
B18: PRODUCTION COST PER PIZZA
B20: Material cost
B21: Water & electricity
B22: Total
B26: INCOME STATEMENT | E26: CASH FLOW STATEMENT
B28: Sales revenue | E28: Cash beginning
B30: - Cost of pizzas sold | E30: Cash in
B31: - Part-time employee | E31: Acc. Receivable collection
B32: - Truck insurance | E32: Sales in cash
B34: - Truck depreciation | E34: Cash out
B35: Monthly profit | E35: Truck purchase
E36: Food supply
E37: Water & electricity
E38: Part-time employee
E39: Truck insurance
E41: Cash end
B45: BALANCE SHEET END OF THE MONTH
B47: ASSETS | E47: LIABILITIES & EQUITY
B48: Gross truck value | E48: Share capital
B49: - Cumulated depreciation | E49: Retained earnings
B50: Net truck value | E50: Monthly profit
B51: Inventory | E51: Owners' equity
B52: Accounts receivable
B53: Cash | E53: Debt to truck supplier
B54: Total assets | E54: Total liabilities & equity

Sheet March
A1: MARCH
B4: I buy the truck for: | C4: 36000 | D4: (to be paid half in March and half in April)
B5: I will use the truck for: | C5: 3 | D5: in total
B6: I visit the supermarket once more to purchase food:
B7: Food supply: | C7: 5000
B8: I sell: | C8: 1000 | D8: to individual customers who all pay in cash
B9: Plus: | C9: 2000 | D9: to a neighbouring company (payment terms: 30 days)
B10: The selling price will be: | C10: 10 | D10: for all customers (individuals & the neighbouring company)
B11: I bear the following additional expenses:
B12: Material cost: | C12: 1.5 | D12: (past inventory & food just bought at the supermarket)
B13: Water & electricity: | C13: 0.5
B14: Part-time employee: | C14: 1000
B15: Truck insurance: | C15: 300
B18: PRODUCTION COST PER PIZZA
B20: Material cost | C20: =C12 -> 1.5
B21: Water & electricity | C21: =C13 -> 0.5
B22: Total | C22: =C20+C21 -> 2
B26: INCOME STATEMENT | E26: CASH FLOW STATEMENT
B28: Sales revenue | C28: =C10*(C8+C9) -> 30000 | E28: Cash beginning | F28: =February!C46 -> 6500
B30: - Cost of pizzas sold | C30: =-C22*(C8+C9) -> -6000 | E30: Cash in
B31: - Part-time employee | C31: =-C14 -> -1000 | E31: Acc. Receivable collection | F31: =February!C45 -> 20000
B32: - Truck insurance | C32: =-C15 -> -300 | E32: Sales in cash | F32: =C8*C10 -> 10000
B34: - Truck depreciation | C34: =-C4/C5/12 -> -1000 | E34: Cash out
B35: Monthly profit | C35: =SUM(C28:C34) -> 21700 | E35: Truck purchase | F35: =-C4/2 -> -18000
E36: Food supply | F36: =-C7 -> -5000
E37: Water & electricity | F37: =-C21*(C8+C9) -> -1500
E38: Part-time employee | F38: =-C14 -> -1000
E39: Truck insurance | F39: =-C15 -> -300
E41: Cash end | F41: =SUM(F28:F39) -> 10700
B45: BALANCE SHEET END OF THE MONTH
B47: ASSETS | E47: LIABILITIES & EQUITY
B48: Gross truck value | C48: =C4 -> 36000 | E48: Share capital | F48: =February!F44 -> 5000
B49: - Cumulated depreciation | C49: =C34 -> -1000 | E49: Retained earnings | F49: =February!F45+February!F46 -> 22000
B50: Net truck value | C50: =C48+C49 -> 35000 | E50: Monthly profit | F50: =C35 -> 21700
B51: Inventory | C51: =February!C44+C7-C20*(C8+C9) -> 1000 | E51: Owners' equity | F51: =SUM(F48:F50) -> 48700
B52: Accounts receivable | C52: =C9*C10 -> 20000
B53: Cash | C53: =F41 -> 10700 | E53: Debt to truck supplier | F53: =C4/2 -> 18000
B54: Total assets | C54: =SUM(C50:C53) -> 66700 | E54: Total liabilities & equity | F54: =SUM(F51:F53) -> 66700

Sheet April-blank
A1: APRIL
B4: I visit the supermarket to purchase food:
B5: Food supply: | C5: 5000
B6: I sell: | C6: 4000 | D6: to a neighbouring company
B7: As of this month, new conditions apply when I'm doing business with this corporate customer:
B8: Selling price: | C8: 10 | D8: (unchanged)
B9: Payment terms: | C9: 60
B10: I still use the truck bought in March to I run the operations and bear the following additional expenses:
B11: Material cost: | C11: 1.5
B12: Water & electricity: | C12: 0.5
B13: Part-time employee: | C13: 1000
B14: Truck insurance: | C14: 300
B17: PRODUCTION COST PER PIZZA
B19: Material cost
B20: Water & electricity
B21: Total
B25: INCOME STATEMENT | E25: CASH FLOW STATEMENT
B27: Sales revenue | E27: Cash beginning
B29: - Cost of pizzas sold | E29: Cash in
B30: - Part-time employee | E30: Acc. Receivable collection
B31: - Truck insurance | E31: Sales in cash
B33: - Truck depreciation | E33: Cash out
B34: Monthly profit | E34: Truck purchase (end)
E35: Food supply
E36: Water & electricity
E37: Part-time employee
E38: Truck insurance
E40: Cash end
B44: BALANCE SHEET END OF THE MONTH
B46: ASSETS | E46: LIABILITIES & EQUITY
B47: Gross truck value | E47: Share capital
B48: - Cumulated depreciation | E48: Retained earnings
B49: Net truck value | E49: Monthly profit
B50: Inventory | E50: Owners' equity
B51: Accounts receivable
B52: Cash | E52: Debt to truck supplier
B53: Total assets | E53: Total liabilities & equity

Sheet April
A1: APRIL
B4: I visit the supermarket to purchase food:
B5: Food supply: | C5: 5000
B6: I sell: | C6: 4000 | D6: to a neighbouring company
B7: As of this month, new conditions apply when I'm doing business with this corporate customer:
B8: Selling price: | C8: 10 | D8: (unchanged)
B9: Payment terms: | C9: 60
B10: I still use the truck bought in March to I run the operations and bear the following additional expenses:
B11: Material cost: | C11: 1.5
B12: Water & electricity: | C12: 0.5
B13: Part-time employee: | C13: 1000
B14: Truck insurance: | C14: 300
B17: PRODUCTION COST PER PIZZA
B19: Material cost | C19: =C11 -> 1.5
B20: Water & electricity | C20: =C12 -> 0.5
B21: Total | C21: =SUM(C19:C20) -> 2
B25: INCOME STATEMENT | E25: CASH FLOW STATEMENT
B27: Sales revenue | C27: =C6*C8 -> 40000 | E27: Cash beginning | F27: =March!C53 -> 10700
B29: - Cost of pizzas sold | C29: =-C21*C6 -> -8000 | E29: Cash in
B30: - Part-time employee | C30: =-C13 -> -1000 | E30: Acc. Receivable collection | F30: =March!C52 -> 20000
B31: - Truck insurance | C31: =-C14 -> -300 | E31: Sales in cash | F31: 0
B33: - Truck depreciation | C33: =March!C34 -> -1000 | E33: Cash out
B34: Monthly profit | C34: =SUM(C27:C33) -> 29700 | E34: Truck purchase (end) | F34: =-March!F53 -> -18000
E35: Food supply | F35: =-C5 -> -5000
E36: Water & electricity | F36: =-C12*C6 -> -2000
E37: Part-time employee | F37: =-C13 -> -1000
E38: Truck insurance | F38: =-C14 -> -300
E40: Cash end | F40: =F27+SUM(F29:F31)+SUM(F33:F38) -> 4400
B44: BALANCE SHEET END OF THE MONTH
B46: ASSETS | E46: LIABILITIES & EQUITY
B47: Gross truck value | C47: =March!C48 -> 36000 | E47: Share capital | F47: =March!F48 -> 5000
B48: - Cumulated depreciation | C48: =March!C49+April!C33 -> -2000 | E48: Retained earnings | F48: =March!F49+March!F50 -> 43700
B49: Net truck value | C49: =SUM(C47:C48) -> 34000 | E49: Monthly profit | F49: =C34 -> 29700
B50: Inventory | C50: =March!C51+C5-C19*C6 -> 0 | E50: Owners' equity | F50: =SUM(F47:F49) -> 78400
B51: Accounts receivable | C51: =C6*C8 -> 40000
B52: Cash | C52: =F40 -> 4400 | E52: Debt to truck supplier | F52: 0
B53: Total assets | C53: =SUM(C49:C52) -> 78400 | E53: Total liabilities & equity | F53: =SUM(F50:F52) -> 78400

Sheet May - blank
A1: MAY
B4: I visit the supermarket to purchase food:
B5: Food supply: | C5: 8000 | D5: (50% cash payment)
B6: I sell: | C6: 5000 | D6: to a neighbouring company
B7: The contract closed with this customer last month still applies:
B8: Selling price: | C8: 10
B9: Payment terms: | C9: 60
B10: I will have to bear the following expenses:
B11: Material cost: | C11: 1.5
B12: Water & electricity: | C12: 0.5
B13: Part-time employee: | C13: 1000
B14: Truck insurance: | C14: 300
B15: At the beginning of the month, I manage to borrow money from Alpha-Bank:
B16: Amount: | C16: 20000 | D16: (principal of the loan)
B17: Interest rate: | C17: 0.01 | D17: per month
B18: I also have to start to pay taxes on my profits:
B19: Tax rate: | C19: =1/3 -> 0.33333333
B22: PRODUCTION COST PER PIZZA
B24: Material cost | C24: 1.5
B25: Water & electricity | C25: 0.5
B26: Total | C26: =C25+C24 -> 2
B29: INCOME STATEMENT
B31: Sales revenue | C31: =C6*C8 -> 50000
B32: - Cost of pizzas sold | C32: =C26*C6 -> 10000
B33: Variable margin | C33: =C31-C32 -> 40000
B34: - Part-time employee | C34: =C13 -> 1000
B35: - Truck insurance | C35: =C14 -> 300
B36: EBITDA | C36: =C33-C34-C35 -> 38700
B37: - Truck depreciation | C37: =1000 -> 1000
B38: Operating Income (EBIT) | C38: =C36-C37 -> 37700
B39: - Interest expenses | C39: =C16*C17 -> 200
B40: Earnings Before Tax | C40: =C38-C39 -> 37500
B41: - Taxes | C41: =C40*C19 -> 12500
B42: Net Income | C42: =C40-C41 -> 25000
B45: CASH FLOW STATEMENT (direct)
B47: Cash beginning | C47: =April!F40 -> 4400
B49: Acc. Receivable collection | C49: =0 -> 0
B50: + Sales in cash | C50: =0 -> 0
B51: - Food supply | C51: =-C5/2 -> -4000
B52: - Water & electricity | C52: =-C25*C6 -> -2500
...

Sheet May - CF analysis
A1: MAY
B4: I visit the supermarket to purchase food:
B5: Food supply: | C5: 8000 | D5: (50% cash payment)
B6: I sell: | C6: 5000 | D6: to a neighbouring company
B7: The contract closed with this customer last month still applies:
B8: Selling price: | C8: 10
B9: Payment terms: | C9: 60
B10: I will have to bear the following expenses:
B11: Material cost: | C11: 1.5
B12: Water & electricity: | C12: 0.5
B13: Part-time employee: | C13: 1000
B14: Truck insurance: | C14: 300
B15: At the beginning of the month, I manage to borrow money from Alpha-Bank:
B16: Amount: | C16: 20000 | D16: (principal of the loan)
B17: Interest rate: | C17: 0.01 | D17: per month
B18: I also have to start to pay taxes on my profits:
B19: Tax rate: | C19: =1/3 -> 0.33333333
B22: PRODUCTION COST PER PIZZA
B24: Material cost | C24: =C11 -> 1.5
B25: Water & electricity | C25: =C12 -> 0.5
B26: Total | C26: =C24+C25 -> 2
B29: INCOME STATEMENT
B31: Sales revenue | C31: =C6*C8 -> 50000
B32: - Cost of pizzas sold | C32: =-C26*C6 -> -10000
B33: Variable margin | C33: =C31+C32 -> 40000
B34: - Part-time employee | C34: =-C13 -> -1000
B35: - Truck insurance | C35: =-C14 -> -300
B36: EBITDA | C36: =SUM(C33:C35) -> 38700
B37: - Truck depreciation | C37: =April!C33 -> -1000
B38: Operating Income (EBIT) | C38: =C36+C37 -> 37700
B39: - Interest expenses | C39: =-C16*C17 -> -200
B40: Earnings Before Tax | C40: =C38+C39 -> 37500
B41: - Taxes | C41: =-C19*C40 -> -12500
B42: Net Income | C42: =C40+C41 -> 25000
B45: CASH FLOW STATEMENT (direct) | E45: CASH FLOW STATEMENT (indirect)
B47: Cash beginning | C47: =April!C52 -> 4400 | E47: Cash beginning
B49: Acc. Receivable collection | C49: 0 | E49: EBIT | H49: Working Capital April:
B50: + Sales in cash | C50: 0 | E50: + Depreciation | H50: Working Capital May:
B51: - Food supply | C51: =-C5/2 -> -4000 | E51: - Increase in Working Capital | H51: Increase in Working Capital:
B52: - Water & electricity | C52: =-C25*C6 -> -2500 | E52: - Interest expenses
...

Sheet May
A1: MAY
B4: I visit the supermarket to purchase food:
B5: Food supply: | C5: 8000 | D5: (50% cash payment)
B6: I sell: | C6: 5000 | D6: to a neighbouring company
B7: The contract closed with this customer last month still applies:
B8: Selling price: | C8: 10
B9: Payment terms: | C9: 60
B10: I will have to bear the following expenses:
B11: Material cost: | C11: 1.5
B12: Water & electricity: | C12: 0.5
B13: Part-time employee: | C13: 1000
B14: Truck insurance: | C14: 300
B15: At the beginning of the month, I manage to borrow money from Alpha-Bank:
B16: Amount: | C16: 20000 | D16: (principal of the loan)
B17: Interest rate: | C17: 0.01 | D17: per month
B18: I also have to start to pay taxes on my profits:
B19: Tax rate: | C19: =1/3 -> 0.33333333
B22: PRODUCTION COST PER PIZZA
B24: Material cost | C24: =C11 -> 1.5
B25: Water & electricity | C25: =C12 -> 0.5
B26: Total | C26: =C24+C25 -> 2
B29: INCOME STATEMENT
B31: Sales revenue | C31: =C6*C8 -> 50000
B32: - Cost of pizzas sold | C32: =-C26*C6 -> -10000
B33: Variable margin | C33: =C31+C32 -> 40000
B34: - Part-time employee | C34: =-C13 -> -1000
B35: - Truck insurance | C35: =-C14 -> -300
B36: EBITDA | C36: =SUM(C33:C35) -> 38700
B37: - Truck depreciation | C37: =April!C33 -> -1000
B38: Operating Income (EBIT) | C38: =C36+C37 -> 37700
B39: - Interest expenses | C39: =-C16*C17 -> -200
B40: Earnings Before Tax | C40: =C38+C39 -> 37500
B41: - Taxes | C41: =-C19*C40 -> -12500
B42: Net Income | C42: =C40+C41 -> 25000
B45: CASH FLOW STATEMENT (direct) | E45: CASH FLOW STATEMENT (indirect)
B47: Cash beginning | C47: =April!C52 -> 4400 | E47: Cash beginning | F47: =C47 -> 4400
B49: Acc. Receivable collection | C49: 0 | E49: EBIT | F49: =C38 -> 37700 | H49: Working Capital April: | I49: =April!C50+April!C51 -> 40000
B50: + Sales in cash | C50: 0 | E50: + Depreciation | F50: =-C37 -> 1000 | H50: Working Capital May: | I50: =C76+C79-F80 -> 86500
B51: - Food supply | C51: =-C5/2 -> -4000 | E51: - Increase in Working Capital | F51: =-I51 -> -46500 | H51: Increase in Working Capital: | I51: =I50-I49 -> 46500
B52: - Water & electricity | C52: =-C25*C6 -> -2500 | E52: - Interest expenses | F52: =C55 -> -200
...
